<?xml version="1.0" encoding="utf-8"?>
<!-- This URDF was automatically created by SolidWorks to URDF Exporter! Originally created by Stephen Brawner (brawner@gmail.com) 
     Commit Version: 1.6.0-4-g7f85cfe  Build Version: 1.6.7995.38578
     For more information, please see http://wiki.ros.org/sw_urdf_exporter -->
<robot
  name="NEW_HAND_7_14">
  <link name="world"/>
  <link
    name="base_link">
    <inertial>
      <origin
        xyz="0.0229889992001183 -0.0589535736179466 0.0450931504750478"
        rpy="0 0 0" />
      <mass
        value="0.0923260250366311" />
      <inertia
        ixx="0.000157834671298758"
        ixy="1.67552394999982E-06"
        ixz="-2.03624787383225E-06"
        iyy="0.000112349532484309"
        iyz="3.30084225768307E-06"
        izz="7.7076995618803E-05" />
    </inertial>
    <visual>
      <origin
        xyz="0 0 0"
        rpy="0 0 0" />
      <geometry>
        <mesh
          filename="base_link.STL" />
      </geometry>
      <material
        name="">
        <color
          rgba="0.752941176470588 0.752941176470588 0.752941176470588 1" />
      </material>
    </visual>
    <collision>
      <origin
        xyz="0 0 0"
        rpy="0 0 0" />
      <geometry>
        <mesh
          filename="base_link.STL" />
      </geometry>
    </collision>
  </link>
  <joint
    name="world_link"
    type="fixed">
    <origin
      xyz="0 0 0"
      rpy="0 0 0" />
    <parent
      link="world" />
    <child
      link="base_link" />
  </joint>
  <link
    name="Thumb_CMC">
    <inertial>
      <origin
        xyz="-0.0235959691055167 0.0225251931415979 0.0175929138775454"
        rpy="0 0 0" />
      <mass
        value="0.00470513936643103" />
      <inertia
        ixx="1.11899230385288E-06"
        ixy="5.20820108682325E-08"
        ixz="-1.39209403588716E-07"
        iyy="1.11995200428266E-06"
        iyz="-4.46312838531224E-08"
        izz="5.93539621429687E-07" />
    </inertial>
    <visual>
      <origin
        xyz="0 0 0"
        rpy="0 0 0" />
      <geometry>
        <mesh
          filename="Thumb_CMC.STL" />
      </geometry>
      <material
        name="">
        <color
          rgba="1 1 1 1" />
      </material>
    </visual>
    <collision>
      <origin
        xyz="0 0 0"
        rpy="0 0 0" />
      <geometry>
        <mesh
          filename="Thumb_CMC.STL" />
      </geometry>
    </collision>
  </link>
  <joint
    name="Th_CMC"
    type="revolute">
    <origin
      xyz="0.0103949901972592 -0.0801396497736802 -0.00161898166752142"
      rpy="1.81199021468476 0.917419447170182 -0.192745517691689" />
    <parent
      link="base_link" />
    <child
      link="Thumb_CMC" />
    <axis
      xyz="0.766044443118979 -0.642787609686538 0" />
    <limit
      lower="0"
      upper="1.8545"
      effort="0"
      velocity="0" />
  </joint>
  <link
    name="Thumb_MCP">
    <inertial>
      <origin
        xyz="-0.00698509061159064 0.0220169747464121 0.0170595291177568"
        rpy="0 0 0" />
      <mass
        value="0.00335471840493084" />
      <inertia
        ixx="5.73393598668486E-07"
        ixy="5.55636825205899E-10"
        ixz="6.24004252624377E-08"
        iyy="6.36180797024836E-07"
        iyz="-1.06972865142351E-09"
        izz="4.35378331182914E-07" />
    </inertial>
    <visual>
      <origin
        xyz="0 0 0"
        rpy="0 0 0" />
      <geometry>
        <mesh
          filename="Thumb_MCP.STL" />
      </geometry>
      <material
        name="">
        <color
          rgba="1 1 1 1" />
      </material>
    </visual>
    <collision>
      <origin
        xyz="0 0 0"
        rpy="0 0 0" />
      <geometry>
        <mesh
          filename="Thumb_MCP.STL" />
      </geometry>
    </collision>
  </link>
  <joint
    name="Th_MCP"
    type="revolute">
    <origin
      xyz="-0.0152503592087255 0 0.0469999941010946"
      rpy="0 -0.201891001612509 0" />
    <parent
      link="Thumb_CMC" />
    <child
      link="Thumb_MCP" />
    <axis
      xyz="0 1 0" />
    <limit
      upper="0"
      lower="-0.9203"
      effort="0"
      velocity="0" />
  </joint>
  <link
    name="Thumb_IP">
    <inertial>
      <origin
        xyz="-0.00965035814633384 0.0382988195196307 0.0168001415764273"
        rpy="0 0 0" />
      <mass
        value="0.00427950781214506" />
      <inertia
        ixx="5.75540487558198E-07"
        ixy="-1.74308322559607E-10"
        ixz="1.10428094841803E-07"
        iyy="5.8363337114812E-07"
        iyz="-2.30105117719501E-10"
        izz="3.13187146818427E-07" />
    </inertial>
    <visual>
      <origin
        xyz="0 0 0"
        rpy="0 0 0" />
      <geometry>
        <mesh
          filename="Thumb_IP.STL" />
      </geometry>
      <material
        name="">
        <color
          rgba="1 1 1 1" />
      </material>
    </visual>
    <collision>
      <origin
        xyz="0 0 0"
        rpy="0 0 0" />
      <geometry>
        <mesh
          filename="Thumb_IP.STL" />
      </geometry>
    </collision>
  </link>
  <joint
    name="Th_IP"
    type="revolute">
    <origin
      xyz="0 -0.0162599854802385 0.04"
      rpy="0 0.0427040475838492 0" />
    <parent
      link="Thumb_MCP" />
    <child
      link="Thumb_IP" />
    <axis
      xyz="0 1 0" />
    <limit
      upper="0"
      lower="-0.7858"
      effort="0"
      velocity="0" />
  </joint>
  <link
    name="Index_Below_MCP">
    <inertial>
      <origin
        xyz="-0.000141739017525552 -0.007414281905249 -0.0158941275770474"
        rpy="0 0 0" />
      <mass
        value="0.00533430928122937" />
      <inertia
        ixx="1.03059750991721E-06"
        ixy="-2.85477156438942E-09"
        ixz="-5.92063718237686E-09"
        iyy="6.30910257692551E-07"
        iyz="-3.26746784074712E-07"
        izz="8.35250630015932E-07" />
    </inertial>
    <visual>
      <origin
        xyz="0 0 0"
        rpy="0 0 0" />
      <geometry>
        <mesh
          filename="Index_Below_MCP.STL" />
      </geometry>
      <material
        name="">
        <color
          rgba="0.698039215686274 0.698039215686274 0.698039215686274 1" />
      </material>
    </visual>
    <collision>
      <origin
        xyz="0 0 0"
        rpy="0 0 0" />
      <geometry>
        <mesh
          filename="Index_Below_MCP.STL" />
      </geometry>
    </collision>
  </link>
  <joint
    name="I_B_MCP"
    type="revolute">
    <origin
      xyz="0.0119549901972592 -0.0906341127127564 0.0986496364816261"
      rpy="-1.5707963267949 0 1.57079631189374" />
    <parent
      link="base_link" />
    <child
      link="Index_Below_MCP" />
    <axis
      xyz="0 0 1" />
    <limit
      upper="0"
      lower="-0.4666"
      effort="0"
      velocity="0" />
  </joint>
  <link
    name="Index_MCP">
    <inertial>
      <origin
        xyz="1.74845297286619E-05 0.012425082459662 -0.00584261155744065"
        rpy="0 0 0" />
      <mass
        value="0.002755942184203" />
      <inertia
        ixx="3.71398920418388E-07"
        ixy="4.40724760964533E-11"
        ixz="5.10520634417057E-11"
        iyy="2.52622034069184E-07"
        iyz="-4.71525953399512E-08"
        izz="3.66973305602768E-07" />
    </inertial>
    <visual>
      <origin
        xyz="0 0 0"
        rpy="0 0 0" />
      <geometry>
        <mesh
          filename="Index_MCP.STL" />
      </geometry>
      <material
        name="">
        <color
          rgba="0.796078431372549 0.823529411764706 0.937254901960784 1" />
      </material>
    </visual>
    <collision>
      <origin
        xyz="0 0 0"
        rpy="0 0 0" />
      <geometry>
        <mesh
          filename="Index_MCP.STL" />
      </geometry>
    </collision>
  </link>
  <joint
    name="I_MCP"
    type="revolute">
    <origin
      xyz="0 -0.028 -0.0205"
      rpy="-3.14159265358979 0 0" />
    <parent
      link="Index_Below_MCP" />
    <child
      link="Index_MCP" />
    <axis
      xyz="1 0 0" />
    <limit
      upper="0"
      lower="-1.8002"
      effort="0"
      velocity="0" />
  </joint>
  <link
    name="Index_PIP">
    <inertial>
      <origin
        xyz="1.91322862938131E-05 0.0102728432221988 -0.00621243408785694"
        rpy="0 0 0" />
      <mass
        value="0.00237210892394413" />
      <inertia
        ixx="2.39005004655757E-07"
        ixy="3.3700673346227E-11"
        ixz="3.67682453124388E-11"
        iyy="2.02579627119856E-07"
        iyz="-3.33240723310131E-09"
        izz="2.33279497210011E-07" />
    </inertial>
    <visual>
      <origin
        xyz="0 0 0"
        rpy="0 0 0" />
      <geometry>
        <mesh
          filename="Index_PIP.STL" />
      </geometry>
      <material
        name="">
        <color
          rgba="0.796078431372549 0.823529411764706 0.937254901960784 1" />
      </material>
    </visual>
    <collision>
      <origin
        xyz="0 0 0"
        rpy="0 0 0" />
      <geometry>
        <mesh
          filename="Index_PIP.STL" />
      </geometry>
    </collision>
  </link>
  <joint
    name="I_PIP"
    type="revolute">
    <origin
      xyz="0 0.0349845407392164 -4.41133227821466E-05"
      rpy="0 0 0" />
    <parent
      link="Index_MCP" />
    <child
      link="Index_PIP" />
    <axis
      xyz="1 0 0" />
    <limit
      upper="0"
      lower="-1.3104"
      effort="0"
      velocity="0" />
  </joint>
  <link
    name="Index_DIP">
    <inertial>
      <origin
        xyz="0.0088745383856826 0.0186542963001512 1.7951750147252E-05"
        rpy="0 0 0" />
      <mass
        value="0.00401062240803133" />
      <inertia
        ixx="5.63158708316372E-07"
        ixy="-6.20177100204777E-08"
        ixz="2.95041218083257E-11"
        iyy="2.03576127281701E-07"
        iyz="2.5595409783033E-10"
        izz="5.37383458551985E-07" />
    </inertial>
    <visual>
      <origin
        xyz="0 0 0"
        rpy="0 0 0" />
      <geometry>
        <mesh
          filename="Index_DIP.STL" />
      </geometry>
      <material
        name="">
        <color
          rgba="0.796078431372549 0.823529411764706 0.937254901960784 1" />
      </material>
    </visual>
    <collision>
      <origin
        xyz="0 0 0"
        rpy="0 0 0" />
      <geometry>
        <mesh
          filename="Index_DIP.STL" />
      </geometry>
    </collision>
  </link>
  <joint
    name="I_DIP"
    type="revolute">
    <origin
      xyz="0 0.028 0"
      rpy="0 1.5707963267949 0" />
    <parent
      link="Index_PIP" />
    <child
      link="Index_DIP" />
    <axis
      xyz="0 0 1" />
    <limit
      upper="0"
      lower="-1.1885"
      effort="0"
      velocity="0" />
  </joint>
  <link
    name="Middle_MCP">
    <inertial>
      <origin
        xyz="-0.0101136002172671 0.0123174814539491 -0.00573714110498205"
        rpy="0 0 0" />
      <mass
        value="0.00272571097624337" />
      <inertia
        ixx="3.60741433432062E-07"
        ixy="4.97055645069262E-11"
        ixz="5.82294784402578E-11"
        iyy="2.4908302309683E-07"
        iyz="-4.6314073428808E-08"
        izz="3.60046241463054E-07" />
    </inertial>
    <visual>
      <origin
        xyz="0 0 0"
        rpy="0 0 0" />
      <geometry>
        <mesh
          filename="Middle_MCP.STL" />
      </geometry>
      <material
        name="">
        <color
          rgba="0.796078431372549 0.823529411764706 0.937254901960784 1" />
      </material>
    </visual>
    <collision>
      <origin
        xyz="0 0 0"
        rpy="0 0 0" />
      <geometry>
        <mesh
          filename="Middle_MCP.STL" />
      </geometry>
    </collision>
  </link>
  <joint
    name="M_MCP"
    type="revolute">
    <origin
      xyz="0.0324520124765686 -0.0595027978004319 0.135649636481626"
      rpy="1.5707963267949 0 1.5707963267949" />
    <parent
      link="base_link" />
    <child
      link="Middle_MCP" />
    <axis
      xyz="1 0 0" />
    <limit
      upper="0"
      lower="-1.7791"
      effort="0"
      velocity="0" />
  </joint>
  <link
    name="Middle_PIP">
    <inertial>
      <origin
        xyz="-0.0101116960869287 0.0102838776437251 -0.00629709978947194"
        rpy="0 0 0" />
      <mass
        value="0.00233862396902497" />
      <inertia
        ixx="2.35929304829107E-07"
        ixy="-3.69258097109355E-13"
        ixz="3.72251798588378E-11"
        iyy="2.00832171761458E-07"
        iyz="-3.66561096906324E-09"
        izz="2.27073981414219E-07" />
    </inertial>
    <visual>
      <origin
        xyz="0 0 0"
        rpy="0 0 0" />
      <geometry>
        <mesh
          filename="Middle_PIP.STL" />
      </geometry>
      <material
        name="">
        <color
          rgba="0.792156862745098 0.819607843137255 0.933333333333333 1" />
      </material>
    </visual>
    <collision>
      <origin
        xyz="0 0 0"
        rpy="0 0 0" />
      <geometry>
        <mesh
          filename="Middle_PIP.STL" />
      </geometry>
    </collision>
  </link>
  <joint
    name="M_PIP"
    type="revolute">
    <origin
      xyz="0 0.0349845407392164 -4.41133227821119E-05"
      rpy="0 0 0" />
    <parent
      link="Middle_MCP" />
    <child
      link="Middle_PIP" />
    <axis
      xyz="1 0 0" />
    <limit
      upper="0"
      lower="-1.2823"
      effort="0"
      velocity="0" />
  </joint>
  <link
    name="Middle_DIP">
    <inertial>
      <origin
        xyz="0.00882563898963759 0.0186497272717144 -0.00951756398313746"
        rpy="0 0 0" />
      <mass
        value="0.00393985996098775" />
      <inertia
        ixx="5.59716352696436E-07"
        ixy="-6.16509165164444E-08"
        ixz="2.39131903634239E-11"
        iyy="2.02161679784652E-07"
        iyz="2.542013817785E-10"
        izz="5.33501808261228E-07" />
    </inertial>
    <visual>
      <origin
        xyz="0 0 0"
        rpy="0 0 0" />
      <geometry>
        <mesh
          filename="Middle_DIP.STL" />
      </geometry>
      <material
        name="">
        <color
          rgba="0.796078431372549 0.823529411764706 0.937254901960784 1" />
      </material>
    </visual>
    <collision>
      <origin
        xyz="0 0 0"
        rpy="0 0 0" />
      <geometry>
        <mesh
          filename="Middle_DIP.STL" />
      </geometry>
    </collision>
  </link>
  <joint
    name="M_DIP"
    type="revolute">
    <origin
      xyz="-0.000595463753748519 0.028 0"
      rpy="0 1.5707963267949 0" />
    <parent
      link="Middle_PIP" />
    <child
      link="Middle_DIP" />
    <axis
      xyz="0 0 1" />
    <limit
      upper="0"
      lower="-1.275"
      effort="0"
      velocity="0" />
  </joint>
  <link
    name="Ring_Below_MCP">
    <inertial>
      <origin
        xyz="0.000141400134023868 0.0074857139011992 -0.0159144514378361"
        rpy="0 0 0" />
      <mass
        value="0.00533806254719222" />
      <inertia
        ixx="1.03534831690712E-06"
        ixy="-2.71243441971051E-09"
        ixz="5.52800832529695E-09"
        iyy="6.29683236282431E-07"
        iyz="3.2850594945562E-07"
        izz="8.398894362912E-07" />
    </inertial>
    <visual>
      <origin
        xyz="0 0 0"
        rpy="0 0 0" />
      <geometry>
        <mesh
          filename="Ring_Below_MCP.STL" />
      </geometry>
      <material
        name="">
        <color
          rgba="0.698039215686274 0.698039215686274 0.698039215686274 1" />
      </material>
    </visual>
    <collision>
      <origin
        xyz="0 0 0"
        rpy="0 0 0" />
      <geometry>
        <mesh
          filename="Ring_Below_MCP.STL" />
      </geometry>
    </collision>
  </link>
  <joint
    name="R_B_MCP"
    type="revolute">
    <origin
      xyz="0.0119549901972592 -0.0486341127127564 0.0986496364816261"
      rpy="1.5707963267949 0 -1.5707963267949" />
    <parent
      link="base_link" />
    <child
      link="Ring_Below_MCP" />
    <axis
      xyz="0 0 1" />
    <limit
      lower="0"
      upper="0.4666"
      effort="0"
      velocity="0" />
  </joint>
  <link
    name="Ring_MCP">
    <inertial>
      <origin
        xyz="1.81948245160032E-05 0.0123593854737641 -0.00587052665391902"
        rpy="0 0 0" />
      <mass
        value="0.00276772493959526" />
      <inertia
        ixx="3.62934432060181E-07"
        ixy="2.59006347729571E-11"
        ixz="4.352494536437E-11"
        iyy="2.51941262923257E-07"
        iyz="-4.48505833302919E-08"
        izz="3.63179228405758E-07" />
    </inertial>
    <visual>
      <origin
        xyz="0 0 0"
        rpy="0 0 0" />
      <geometry>
        <mesh
          filename="Ring_MCP.STL" />
      </geometry>
      <material
        name="">
        <color
          rgba="0.796078431372549 0.823529411764706 0.937254901960784 1" />
      </material>
    </visual>
    <collision>
      <origin
        xyz="0 0 0"
        rpy="0 0 0" />
      <geometry>
        <mesh
          filename="Ring_MCP.STL" />
      </geometry>
    </collision>
  </link>
  <joint
    name="R_MCP"
    type="revolute">
    <origin
      xyz="0 0.028 -0.0205"
      rpy="3.14159265358979 0 3.14159263869106" />
    <parent
      link="Ring_Below_MCP" />
    <child
      link="Ring_MCP" />
    <axis
      xyz="1 0 0" />
    <limit
      upper="0"
      lower="-1.7553"
      effort="0"
      velocity="0" />
  </joint>
  <link
    name="Ring_PIP">
    <inertial>
      <origin
        xyz="1.82711535060415E-05 0.0103252304355742 -0.00628747443583751"
        rpy="0 0 0" />
      <mass
        value="0.00234637206717093" />
      <inertia
        ixx="2.36074471265175E-07"
        ixy="7.75187690709087E-12"
        ixz="1.58152430137294E-11"
        iyy="2.01399401299851E-07"
        iyz="-3.30872238950354E-09"
        izz="2.28648255064159E-07" />
    </inertial>
    <visual>
      <origin
        xyz="0 0 0"
        rpy="0 0 0" />
      <geometry>
        <mesh
          filename="Ring_PIP.STL" />
      </geometry>
      <material
        name="">
        <color
          rgba="0.796078431372549 0.823529411764706 0.937254901960784 1" />
      </material>
    </visual>
    <collision>
      <origin
        xyz="0 0 0"
        rpy="0 0 0" />
      <geometry>
        <mesh
          filename="Ring_PIP.STL" />
      </geometry>
    </collision>
  </link>
  <joint
    name="R_PIP"
    type="revolute">
    <origin
      xyz="0 0.0349845407392165 -4.41133227821258E-05"
      rpy="0 0 0" />
    <parent
      link="Ring_MCP" />
    <child
      link="Ring_PIP" />
    <axis
      xyz="1 0 0" />
    <limit
      upper="0"
      lower="-1.273"
      effort="0"
      velocity="0" />
  </joint>
  <link
    name="Ring_DIP">
    <inertial>
      <origin
        xyz="0.00880902065251336 0.0186629590447163 1.83065773381175E-05"
        rpy="0 0 0" />
      <mass
        value="0.00392874646199753" />
      <inertia
        ixx="5.59544946557029E-07"
        ixy="-6.18614604312533E-08"
        ixz="2.4163672660381E-11"
        iyy="2.0175897550917E-07"
        iyz="2.55747471336562E-10"
        izz="5.33045911374577E-07" />
    </inertial>
    <visual>
      <origin
        xyz="0 0 0"
        rpy="0 0 0" />
      <geometry>
        <mesh
          filename="Ring_DIP.STL" />
      </geometry>
      <material
        name="">
        <color
          rgba="0.796078431372549 0.823529411764706 0.937254901960784 1" />
      </material>
    </visual>
    <collision>
      <origin
        xyz="0 0 0"
        rpy="0 0 0" />
      <geometry>
        <mesh
          filename="Ring_DIP.STL" />
      </geometry>
    </collision>
  </link>
  <joint
    name="R_DIP"
    type="revolute">
    <origin
      xyz="0 0.028 0"
      rpy="0 1.5707963267949 0" />
    <parent
      link="Ring_PIP" />
    <child
      link="Ring_DIP" />
    <axis
      xyz="0 0 1" />
    <limit
      upper="0"
      lower="-1.2842"
      effort="0"
      velocity="0" />
  </joint>
  <link
    name="Pinky_Below_MCP">
    <inertial>
      <origin
        xyz="-0.00016822714488484 -0.00805589921565376 0.0162001246092224"
        rpy="0 0 0" />
      <mass
        value="0.00512816464476324" />
      <inertia
        ixx="9.99698557391452E-07"
        ixy="2.18278350034049E-08"
        ixz="-1.56085769430749E-08"
        iyy="6.10313689694142E-07"
        iyz="3.14479368818669E-07"
        izz="7.98354678968584E-07" />
    </inertial>
    <visual>
      <origin
        xyz="0 0 0"
        rpy="0 0 0" />
      <geometry>
        <mesh
          filename="Pinky_Below_MCP.STL" />
      </geometry>
      <material
        name="">
        <color
          rgba="0.698039215686274 0.698039215686274 0.698039215686274 1" />
      </material>
    </visual>
    <collision>
      <origin
        xyz="0 0 0"
        rpy="0 0 0" />
      <geometry>
        <mesh
          filename="Pinky_Below_MCP.STL" />
      </geometry>
    </collision>
  </link>
  <joint
    name="P_B_MCP"
    type="revolute">
    <origin
      xyz="0.011955 -0.027634 0.09865"
      rpy="-1.5708 0 -1.5708" />
    <parent
      link="base_link" />
    <child
      link="Pinky_Below_MCP" />
    <axis
      xyz="0 0 1" />
    <limit
      upper="0"
      lower="-0.6872"
      effort="0"
      velocity="0" />
  </joint>
  <link
    name="Pinky_MCP">
    <inertial>
      <origin
        xyz="1.75554955959903E-05 0.0123862857722914 -0.00586906537761597"
        rpy="0 0 0" />
      <mass
        value="0.00275274576508523" />
      <inertia
        ixx="3.66135316485618E-07"
        ixy="5.2281213787533E-11"
        ixz="5.20268126521755E-11"
        iyy="2.51983299258902E-07"
        iyz="-4.56232322526544E-08"
        izz="3.63835747168652E-07" />
    </inertial>
    <visual>
      <origin
        xyz="0 0 0"
        rpy="0 0 0" />
      <geometry>
        <mesh
          filename="Pinky_MCP.STL" />
      </geometry>
      <material
        name="">
        <color
          rgba="0.796078431372549 0.823529411764706 0.937254901960784 1" />
      </material>
    </visual>
    <collision>
      <origin
        xyz="0 0 0"
        rpy="0 0 0" />
      <geometry>
        <mesh
          filename="Pinky_MCP.STL" />
      </geometry>
    </collision>
  </link>
  <joint
    name="P_MCP"
    type="revolute">
    <origin
      xyz="0 -0.028 0.0205"
      rpy="0 0 3.1416" />
    <parent
      link="Pinky_Below_MCP" />
    <child
      link="Pinky_MCP" />
    <axis
      xyz="1 0 0" />
    <limit
      upper="0"
      lower="-1.7269"
      effort="0"
      velocity="0" />
  </joint>
  <link
    name="Pinky_PIP">
    <inertial>
      <origin
        xyz="1.74613939590007E-05 0.0103551539568034 -0.00633662510888196"
        rpy="0 0 0" />
      <mass
        value="0.00234098594407861" />
      <inertia
        ixx="2.3604645358024E-07"
        ixy="-1.81481552856187E-11"
        ixz="6.6232059087801E-11"
        iyy="2.01338905933099E-07"
        iyz="-3.58240052840539E-09"
        izz="2.29068935661681E-07" />
    </inertial>
    <visual>
      <origin
        xyz="0 0 0"
        rpy="0 0 0" />
      <geometry>
        <mesh
          filename="Pinky_PIP.STL" />
      </geometry>
      <material
        name="">
        <color
          rgba="0.796078431372549 0.823529411764706 0.937254901960784 1" />
      </material>
    </visual>
    <collision>
      <origin
        xyz="0 0 0"
        rpy="0 0 0" />
      <geometry>
        <mesh
          filename="Pinky_PIP.STL" />
      </geometry>
    </collision>
  </link>
  <joint
    name="P_PIP"
    type="revolute">
    <origin
      xyz="0 0.034985 -4.4113E-05"
      rpy="0 0 0" />
    <parent
      link="Pinky_MCP" />
    <child
      link="Pinky_PIP" />
    <axis
      xyz="1 0 0" />
    <limit
      upper="0"
      lower="-1.2573"
      effort="0"
      velocity="0" />
  </joint>
  <link
    name="Pinky_DIP">
    <inertial>
      <origin
        xyz="0.00857258027621421 0.0152163338013744 2.31261014923163E-05"
        rpy="0 0 0" />
      <mass
        value="0.00310861620743108" />
      <inertia
        ixx="3.21155921167126E-07"
        ixy="-4.50241167853334E-08"
        ixz="7.08897970179819E-12"
        iyy="1.56377785853672E-07"
        iyz="7.86152162223636E-12"
        izz="3.02201519980175E-07" />
    </inertial>
    <visual>
      <origin
        xyz="0 0 0"
        rpy="0 0 0" />
      <geometry>
        <mesh
          filename="Pinky_DIP.STL" />
      </geometry>
      <material
        name="">
        <color
          rgba="0.796078431372549 0.823529411764706 0.937254901960784 1" />
      </material>
    </visual>
    <collision>
      <origin
        xyz="0 0 0"
        rpy="0 0 0" />
      <geometry>
        <mesh
          filename="Pinky_DIP.STL" />
      </geometry>
    </collision>
  </link>
  <joint
    name="P_DIP"
    type="revolute">
    <origin
      xyz="0 0.028 0"
      rpy="0 1.5708 0" />
    <parent
      link="Pinky_PIP" />
    <child
      link="Pinky_DIP" />
    <axis
      xyz="0 0 1" />
    <limit
      upper="0"
      lower="-1.2577"
      effort="0"
      velocity="0" />
  </joint>
</robot>